Workbook

Sheet Project
A1: Contributor | B1: Project ID | C1: List of contributors | D1: Description | E1: BRA version
E2: Template-v2-2.bra
A4: Sheet Name | B4: Review End Line
A5: References
A6: Circuits
A7: Connections
A8: FRG
B9: Note: fill in "1" if you do not register any data

Sheet References
A1: =IFERROR(__xludf.DUMMYFUNCTION("IMPORTRANGE(Settings!$A$2,""wbReferences!A1:W1"")"),"Reference ID") -> Reference ID | B1: =IFERROR(__xludf.DUMMYFUNCTION("""COMPUTED_VALUE"""),"Doc. Link") -> Doc. Link | C1: =IFERROR(__xludf.DUMMYFUNCTION("""COMPUTED_VALUE"""),"BibTex link") -> BibTex link | D1: =IFERROR(__xludf.DUMMYFUNCTION("""COMPUTED_VALUE"""),"DOI") -> DOI | E1: =IFERROR(__xludf.DUMMYFUNCTION("""COMPUTED_VALUE"""),"BibTex ") -> BibTex | F1: =IFERROR(__xludf.DUMMYFUNCTION("""COMPUTED_VALUE"""),"Litterature type") -> Litterature type | G1: =IFERROR(__xludf.DUMMYFUNCTION("""COMPUTED_VALUE"""),"Type") -> Type | H1: =IFERROR(__xludf.DUMMYFUNCTION("""COMPUTED_VALUE"""),"Authors") -> Authors | I1: =IFERROR(__xludf.DUMMYFUNCTION("""COMPUTED_VALUE"""),"Title") -> Title | J1: =IFERROR(__xludf.DUMMYFUNCTION("""COMPUTED_VALUE"""),"Journal names") -> Journal names | K1: =IFERROR(__xludf.DUMMYFUNCTION("""COMPUTED_VALUE"""),"Alternative URL") -> Alternative URL | L1: =IFERROR(__xludf.DUMMYFUNCTION("""COMPUTED_VALUE"""),"Contributor") -> Contributor | M1: =IFERROR(__xludf.DUMMYFUNCTION("""COMPUTED_VALUE"""),"Project ID") -> Project ID | N1: =IFERROR(__xludf.DUMMYFUNCTION("""COMPUTED_VALUE"""),"WBIF pull request") -> WBIF pull request | O1: =IFERROR(__xludf.DUMMYFUNCTION("""COMPUTED_VALUE"""),"WBIF copied") -> WBIF copied | P1: =IFERROR(__xludf.DUMMYFUNCTION("""COMPUTED_VALUE"""),"Review results") -> Review results | Q1: =IFERROR(__xludf.DUMMYFUNCTION("""COMPUTED_VALUE"""),"Auto Error Codes") -> Auto Error Codes | R1: =IFERROR(__xludf.DUMMYFUNCTION("""COMPUTED_VALUE"""),"Error Code-1") -> Error Code-1 | S1: =IFERROR(__xludf.DUMMYFUNCTION("""COMPUTED_VALUE"""),"Error Code-2") -> Error Code-2 | T1: =IFERROR(__xludf.DUMMYFUNCTION("""COMPUTED_VALUE"""),"Other Error Codes") -> Other Error Codes | U1: =IFERROR(__xludf.DUMMYFUNCTION("""COMPUTED_VALUE"""),"Review comments") -> Review comments | V1: =IFERROR(__xludf.DUMMYFUNCTION("""COMPUTED_VALUE"""),"Reviewer") -> Reviewer | W1: =IFERROR(__xludf.DUMMYFUNCTION("""COMPUTED_VALUE"""),"Reviewed date") -> Reviewed date
A2: =IFERROR(__xludf.DUMMYFUNCTION("IF(ISBLANK(E2), ""(no BibTex)"", CONCATENATE(REGEXEXTRACT(SUBSTITUTE($E2, ""_"", """"),""@.+{(.+)\d{4}""),"", "",REGEXEXTRACT($E2,""@.+{.+(\d{4}.*),"")))"),"(no BibTex)") -> (no BibTex) | B2: =IF(ISBLANK(D2),IF(ISBLANK(K2),"-",HYPERLINK(K2,"DOC(alt)")), HYPERLINK(CONCAT("https://www.doi.org/",D2),"DOC")) -> - | C2: =IF(ISBLANK(D2),"(no DOI)", HYPERLINK(CONCAT("https://www.doi2bib.org/bib/",D2),"BIB")) -> (no DOI) | G2: =IFERROR(__xludf.DUMMYFUNCTION("IF(ISBLANK(E2),""(no BibTex)"",PROPER(REGEXEXTRACT($E2,""@(.+){"")))"),"(no BibTex)") -> (no BibTex) | H2: =IFERROR(__xludf.DUMMYFUNCTION("IF(ISBLANK(E2),""(no BibTex)"",SUBSTITUTE(IFNA(REGEXEXTRACT($E2,""author += +{(.+)}""),REGEXEXTRACT($E2,""editor *= *{(.+)}"")),"" and"", "",""))"),"(no BibTex)") -> (no BibTex) | I2: =IFERROR(__xludf.DUMMYFUNCTION("IF(ISBLANK(E2),""(no BibTex)"",REGEXEXTRACT($E2,""title *= *{(.+)}""))"),"(no BibTex)") -> (no BibTex) | J2: =IFERROR(__xludf.DUMMYFUNCTION("IFNA(IFNA(REGEXEXTRACT($E2,""journal *= *{(.+)}""), REGEXEXTRACT($E2,""booktitle *= *{(.+)}"")), ""-"")"),"-") -> -
A3: =IFERROR(__xludf.DUMMYFUNCTION("IF(ISBLANK(E3), ""(no BibTex)"", CONCATENATE(REGEXEXTRACT(SUBSTITUTE($E3, ""_"", """"),""@.+{(.+)\d{4}""),"", "",REGEXEXTRACT($E3,""@.+{.+(\d{4}.*),"")))"),"(no BibTex)") -> (no BibTex) | B3: =IF(ISBLANK(D3),IF(ISBLANK(K3),"-",HYPERLINK(K3,"DOC(alt)")), HYPERLINK(CONCAT("https://www.doi.org/",D3),"DOC")) -> - | C3: =IF(ISBLANK(D3),"(no DOI)", HYPERLINK(CONCAT("https://www.doi2bib.org/bib/",D3),"BIB")) -> (no DOI) | G3: =IFERROR(__xludf.DUMMYFUNCTION("IF(ISBLANK(E3),""(no BibTex)"",PROPER(REGEXEXTRACT($E3,""@(.+){"")))"),"(no BibTex)") -> (no BibTex) | H3: =IFERROR(__xludf.DUMMYFUNCTION("IF(ISBLANK(E3),""(no BibTex)"",SUBSTITUTE(IFNA(REGEXEXTRACT($E3,""author += +{(.+)}""),REGEXEXTRACT($E3,""editor *= *{(.+)}"")),"" and"", "",""))"),"(no BibTex)") -> (no BibTex) | I3: =IFERROR(__xludf.DUMMYFUNCTION("IF(ISBLANK(E3),""(no BibTex)"",REGEXEXTRACT($E3,""title *= *{(.+)}""))"),"(no BibTex)") -> (no BibTex) | J3: =IFERROR(__xludf.DUMMYFUNCTION("IFNA(IFNA(REGEXEXTRACT($E3,""journal *= *{(.+)}""), REGEXEXTRACT($E3,""booktitle *= *{(.+)}"")), ""-"")"),"-") -> -
A4: =IFERROR(__xludf.DUMMYFUNCTION("IF(ISBLANK(E4), ""(no BibTex)"", CONCATENATE(REGEXEXTRACT(SUBSTITUTE($E4, ""_"", """"),""@.+{(.+)\d{4}""),"", "",REGEXEXTRACT($E4,""@.+{.+(\d{4}.*),"")))"),"(no BibTex)") -> (no BibTex) | B4: =IF(ISBLANK(D4),IF(ISBLANK(K4),"-",HYPERLINK(K4,"DOC(alt)")), HYPERLINK(CONCAT("https://www.doi.org/",D4),"DOC")) -> - | C4: =IF(ISBLANK(D4),"(no DOI)", HYPERLINK(CONCAT("https://www.doi2bib.org/bib/",D4),"BIB")) -> (no DOI) | G4: =IFERROR(__xludf.DUMMYFUNCTION("IF(ISBLANK(E4),""(no BibTex)"",PROPER(REGEXEXTRACT($E4,""@(.+){"")))"),"(no BibTex)") -> (no BibTex) | H4: =IFERROR(__xludf.DUMMYFUNCTION("IF(ISBLANK(E4),""(no BibTex)"",SUBSTITUTE(IFNA(REGEXEXTRACT($E4,""author += +{(.+)}""),REGEXEXTRACT($E4,""editor *= *{(.+)}"")),"" and"", "",""))"),"(no BibTex)") -> (no BibTex) | I4: =IFERROR(__xludf.DUMMYFUNCTION("IF(ISBLANK(E4),""(no BibTex)"",REGEXEXTRACT($E4,""title *= *{(.+)}""))"),"(no BibTex)") -> (no BibTex) | J4: =IFERROR(__xludf.DUMMYFUNCTION("IFNA(IFNA(REGEXEXTRACT($E4,""journal *= *{(.+)}""), REGEXEXTRACT($E4,""booktitle *= *{(.+)}"")), ""-"")"),"-") -> -
A5: =IFERROR(__xludf.DUMMYFUNCTION("IF(ISBLANK(E5), ""(no BibTex)"", CONCATENATE(REGEXEXTRACT(SUBSTITUTE($E5, ""_"", """"),""@.+{(.+)\d{4}""),"", "",REGEXEXTRACT($E5,""@.+{.+(\d{4}.*),"")))"),"(no BibTex)") -> (no BibTex) | B5: =IF(ISBLANK(D5),IF(ISBLANK(K5),"-",HYPERLINK(K5,"DOC(alt)")), HYPERLINK(CONCAT("https://www.doi.org/",D5),"DOC")) -> - | C5: =IF(ISBLANK(D5),"(no DOI)", HYPERLINK(CONCAT("https://www.doi2bib.org/bib/",D5),"BIB")) -> (no DOI) | G5: =IFERROR(__xludf.DUMMYFUNCTION("IF(ISBLANK(E5),""(no BibTex)"",PROPER(REGEXEXTRACT($E5,""@(.+){"")))"),"(no BibTex)") -> (no BibTex) | H5: =IFERROR(__xludf.DUMMYFUNCTION("IF(ISBLANK(E5),""(no BibTex)"",SUBSTITUTE(IFNA(REGEXEXTRACT($E5,""author += +{(.+)}""),REGEXEXTRACT($E5,""editor *= *{(.+)}"")),"" and"", "",""))"),"(no BibTex)") -> (no BibTex) | I5: =IFERROR(__xludf.DUMMYFUNCTION("IF(ISBLANK(E5),""(no BibTex)"",REGEXEXTRACT($E5,""title *= *{(.+)}""))"),"(no BibTex)") -> (no BibTex) | J5: =IFERROR(__xludf.DUMMYFUNCTION("IFNA(IFNA(REGEXEXTRACT($E5,""journal *= *{(.+)}""), REGEXEXTRACT($E5,""booktitle *= *{(.+)}"")), ""-"")"),"-") -> -
A6: =IFERROR(__xludf.DUMMYFUNCTION("IF(ISBLANK(E6), ""(no BibTex)"", CONCATENATE(REGEXEXTRACT(SUBSTITUTE($E6, ""_"", """"),""@.+{(.+)\d{4}""),"", "",REGEXEXTRACT($E6,""@.+{.+(\d{4}.*),"")))"),"(no BibTex)") -> (no BibTex) | B6: =IF(ISBLANK(D6),IF(ISBLANK(K6),"-",HYPERLINK(K6,"DOC(alt)")), HYPERLINK(CONCAT("https://www.doi.org/",D6),"DOC")) -> - | C6: =IF(ISBLANK(D6),"(no DOI)", HYPERLINK(CONCAT("https://www.doi2bib.org/bib/",D6),"BIB")) -> (no DOI) | G6: =IFERROR(__xludf.DUMMYFUNCTION("IF(ISBLANK(E6),""(no BibTex)"",PROPER(REGEXEXTRACT($E6,""@(.+){"")))"),"(no BibTex)") -> (no BibTex) | H6: =IFERROR(__xludf.DUMMYFUNCTION("IF(ISBLANK(E6),""(no BibTex)"",SUBSTITUTE(IFNA(REGEXEXTRACT($E6,""author += +{(.+)}""),REGEXEXTRACT($E6,""editor *= *{(.+)}"")),"" and"", "",""))"),"(no BibTex)") -> (no BibTex) | I6: =IFERROR(__xludf.DUMMYFUNCTION("IF(ISBLANK(E6),""(no BibTex)"",REGEXEXTRACT($E6,""title *= *{(.+)}""))"),"(no BibTex)") -> (no BibTex) | J6: =IFERROR(__xludf.DUMMYFUNCTION("IFNA(IFNA(REGEXEXTRACT($E6,""journal *= *{(.+)}""), REGEXEXTRACT($E6,""booktitle *= *{(.+)}"")), ""-"")"),"-") -> -
A7: =IFERROR(__xludf.DUMMYFUNCTION("IF(ISBLANK(E7), ""(no BibTex)"", CONCATENATE(REGEXEXTRACT(SUBSTITUTE($E7, ""_"", """"),""@.+{(.+)\d{4}""),"", "",REGEXEXTRACT($E7,""@.+{.+(\d{4}.*),"")))"),"(no BibTex)") -> (no BibTex) | B7: =IF(ISBLANK(D7),IF(ISBLANK(K7),"-",HYPERLINK(K7,"DOC(alt)")), HYPERLINK(CONCAT("https://www.doi.org/",D7),"DOC")) -> - | C7: =IF(ISBLANK(D7),"(no DOI)", HYPERLINK(CONCAT("https://www.doi2bib.org/bib/",D7),"BIB")) -> (no DOI) | G7: =IFERROR(__xludf.DUMMYFUNCTION("IF(ISBLANK(E7),""(no BibTex)"",PROPER(REGEXEXTRACT($E7,""@(.+){"")))"),"(no BibTex)") -> (no BibTex) | H7: =IFERROR(__xludf.DUMMYFUNCTION("IF(ISBLANK(E7),""(no BibTex)"",SUBSTITUTE(IFNA(REGEXEXTRACT($E7,""author += +{(.+)}""),REGEXEXTRACT($E7,""editor *= *{(.+)}"")),"" and"", "",""))"),"(no BibTex)") -> (no BibTex) | I7: =IFERROR(__xludf.DUMMYFUNCTION("IF(ISBLANK(E7),""(no BibTex)"",REGEXEXTRACT($E7,""title *= *{(.+)}""))"),"(no BibTex)") -> (no BibTex) | J7: =IFERROR(__xludf.DUMMYFUNCTION("IFNA(IFNA(REGEXEXTRACT($E7,""journal *= *{(.+)}""), REGEXEXTRACT($E7,""booktitle *= *{(.+)}"")), ""-"")"),"-") -> -
A8: =IFERROR(__xludf.DUMMYFUNCTION("IF(ISBLANK(E8), ""(no BibTex)"", CONCATENATE(REGEXEXTRACT(SUBSTITUTE($E8, ""_"", """"),""@.+{(.+)\d{4}""),"", "",REGEXEXTRACT($E8,""@.+{.+(\d{4}.*),"")))"),"(no BibTex)") -> (no BibTex) | B8: =IF(ISBLANK(D8),IF(ISBLANK(K8),"-",HYPERLINK(K8,"DOC(alt)")), HYPERLINK(CONCAT("https://www.doi.org/",D8),"DOC")) -> - | C8: =IF(ISBLANK(D8),"(no DOI)", HYPERLINK(CONCAT("https://www.doi2bib.org/bib/",D8),"BIB")) -> (no DOI) | G8: =IFERROR(__xludf.DUMMYFUNCTION("IF(ISBLANK(E8),""(no BibTex)"",PROPER(REGEXEXTRACT($E8,""@(.+){"")))"),"(no BibTex)") -> (no BibTex) | H8: =IFERROR(__xludf.DUMMYFUNCTION("IF(ISBLANK(E8),""(no BibTex)"",SUBSTITUTE(IFNA(REGEXEXTRACT($E8,""author += +{(.+)}""),REGEXEXTRACT($E8,""editor *= *{(.+)}"")),"" and"", "",""))"),"(no BibTex)") -> (no BibTex) | I8: =IFERROR(__xludf.DUMMYFUNCTION("IF(ISBLANK(E8),""(no BibTex)"",REGEXEXTRACT($E8,""title *= *{(.+)}""))"),"(no BibTex)") -> (no BibTex) | J8: =IFERROR(__xludf.DUMMYFUNCTION("IFNA(IFNA(REGEXEXTRACT($E8,""journal *= *{(.+)}""), REGEXEXTRACT($E8,""booktitle *= *{(.+)}"")), ""-"")"),"-") -> -
A9: =IFERROR(__xludf.DUMMYFUNCTION("IF(ISBLANK(E9), ""(no BibTex)"", CONCATENATE(REGEXEXTRACT(SUBSTITUTE($E9, ""_"", """"),""@.+{(.+)\d{4}""),"", "",REGEXEXTRACT($E9,""@.+{.+(\d{4}.*),"")))"),"(no BibTex)") -> (no BibTex) | B9: =IF(ISBLANK(D9),IF(ISBLANK(K9),"-",HYPERLINK(K9,"DOC(alt)")), HYPERLINK(CONCAT("https://www.doi.org/",D9),"DOC")) -> - | C9: =IF(ISBLANK(D9),"(no DOI)", HYPERLINK(CONCAT("https://www.doi2bib.org/bib/",D9),"BIB")) -> (no DOI) | G9: =IFERROR(__xludf.DUMMYFUNCTION("IF(ISBLANK(E9),""(no BibTex)"",PROPER(REGEXEXTRACT($E9,""@(.+){"")))"),"(no BibTex)") -> (no BibTex) | H9: =IFERROR(__xludf.DUMMYFUNCTION("IF(ISBLANK(E9),""(no BibTex)"",SUBSTITUTE(IFNA(REGEXEXTRACT($E9,""author += +{(.+)}""),REGEXEXTRACT($E9,""editor *= *{(.+)}"")),"" and"", "",""))"),"(no BibTex)") -> (no BibTex) | I9: =IFERROR(__xludf.DUMMYFUNCTION("IF(ISBLANK(E9),""(no BibTex)"",REGEXEXTRACT($E9,""title *= *{(.+)}""))"),"(no BibTex)") -> (no BibTex) | J9: =IFERROR(__xludf.DUMMYFUNCTION("IFNA(IFNA(REGEXEXTRACT($E9,""journal *= *{(.+)}""), REGEXEXTRACT($E9,""booktitle *= *{(.+)}"")), ""-"")"),"-") -> -
A10: =IFERROR(__xludf.DUMMYFUNCTION("IF(ISBLANK(E10), ""(no BibTex)"", CONCATENATE(REGEXEXTRACT(SUBSTITUTE($E10, ""_"", """"),""@.+{(.+)\d{4}""),"", "",REGEXEXTRACT($E10,""@.+{.+(\d{4}.*),"")))"),"(no BibTex)") -> (no BibTex) | B10: =IF(ISBLANK(D10),IF(ISBLANK(K10),"-",HYPERLINK(K10,"DOC(alt)")), HYPERLINK(CONCAT("https://www.doi.org/",D10),"DOC")) -> - | C10: =IF(ISBLANK(D10),"(no DOI)", HYPERLINK(CONCAT("https://www.doi2bib.org/bib/",D10),"BIB")) -> (no DOI) | G10: =IFERROR(__xludf.DUMMYFUNCTION("IF(ISBLANK(E10),""(no BibTex)"",PROPER(REGEXEXTRACT($E10,""@(.+){"")))"),"(no BibTex)") -> (no BibTex) | H10: =IFERROR(__xludf.DUMMYFUNCTION("IF(ISBLANK(E10),""(no BibTex)"",SUBSTITUTE(IFNA(REGEXEXTRACT($E10,""author += +{(.+)}""),REGEXEXTRACT($E10,""editor *= *{(.+)}"")),"" and"", "",""))"),"(no BibTex)") -> (no BibTex) | I10: =IFERROR(__xludf.DUMMYFUNCTION("IF(ISBLANK(E10),""(no BibTex)"",REGEXEXTRACT($E10,""title *= *{(.+)}""))"),"(no BibTex)") -> (no BibTex) | J10: =IFERROR(__xludf.DUMMYFUNCTION("IFNA(IFNA(REGEXEXTRACT($E10,""journal *= *{(.+)}""), REGEXEXTRACT($E10,""booktitle *= *{(.+)}"")), ""-"")"),"-") -> -
A11: =IFERROR(__xludf.DUMMYFUNCTION("IF(ISBLANK(E11), ""(no BibTex)"", CONCATENATE(REGEXEXTRACT(SUBSTITUTE($E11, ""_"", """"),""@.+{(.+)\d{4}""),"", "",REGEXEXTRACT($E11,""@.+{.+(\d{4}.*),"")))"),"(no BibTex)") -> (no BibTex) | B11: =IF(ISBLANK(D11),IF(ISBLANK(K11),"-",HYPERLINK(K11,"DOC(alt)")), HYPERLINK(CONCAT("https://www.doi.org/",D11),"DOC")) -> - | C11: =IF(ISBLANK(D11),"(no DOI)", HYPERLINK(CONCAT("https://www.doi2bib.org/bib/",D11),"BIB")) -> (no DOI) | G11: =IFERROR(__xludf.DUMMYFUNCTION("IF(ISBLANK(E11),""(no BibTex)"",PROPER(REGEXEXTRACT($E11,""@(.+){"")))"),"(no BibTex)") -> (no BibTex) | H11: =IFERROR(__xludf.DUMMYFUNCTION("IF(ISBLANK(E11),""(no BibTex)"",SUBSTITUTE(IFNA(REGEXEXTRACT($E11,""author += +{(.+)}""),REGEXEXTRACT($E11,""editor *= *{(.+)}"")),"" and"", "",""))"),"(no BibTex)") -> (no BibTex) | I11: =IFERROR(__xludf.DUMMYFUNCTION("IF(ISBLANK(E11),""(no BibTex)"",REGEXEXTRACT($E11,""title *= *{(.+)}""))"),"(no BibTex)") -> (no BibTex) | J11: =IFERROR(__xludf.DUMMYFUNCTION("IFNA(IFNA(REGEXEXTRACT($E11,""journal *= *{(.+)}""), REGEXEXTRACT($E11,""booktitle *= *{(.+)}"")), ""-"")"),"-") -> -
A12: =IFERROR(__xludf.DUMMYFUNCTION("IF(ISBLANK(E12), ""(no BibTex)"", CONCATENATE(REGEXEXTRACT(SUBSTITUTE($E12, ""_"", """"),""@.+{(.+)\d{4}""),"", "",REGEXEXTRACT($E12,""@.+{.+(\d{4}.*),"")))"),"(no BibTex)") -> (no BibTex) | B12: =IF(ISBLANK(D12),IF(ISBLANK(K12),"-",HYPERLINK(K12,"DOC(alt)")), HYPERLINK(CONCAT("https://www.doi.org/",D12),"DOC")) -> - | C12: =IF(ISBLANK(D12),"(no DOI)", HYPERLINK(CONCAT("https://www.doi2bib.org/bib/",D12),"BIB")) -> (no DOI) | G12: =IFERROR(__xludf.DUMMYFUNCTION("IF(ISBLANK(E12),""(no BibTex)"",PROPER(REGEXEXTRACT($E12,""@(.+){"")))"),"(no BibTex)") -> (no BibTex) | H12: =IFERROR(__xludf.DUMMYFUNCTION("IF(ISBLANK(E12),""(no BibTex)"",SUBSTITUTE(IFNA(REGEXEXTRACT($E12,""author += +{(.+)}""),REGEXEXTRACT($E12,""editor *= *{(.+)}"")),"" and"", "",""))"),"(no BibTex)") -> (no BibTex) | I12: =IFERROR(__xludf.DUMMYFUNCTION("IF(ISBLANK(E12),""(no BibTex)"",REGEXEXTRACT($E12,""title *= *{(.+)}""))"),"(no BibTex)") -> (no BibTex) | J12: =IFERROR(__xludf.DUMMYFUNCTION("IFNA(IFNA(REGEXEXTRACT($E12,""journal *= *{(.+)}""), REGEXEXTRACT($E12,""booktitle *= *{(.+)}"")), ""-"")"),"-") -> -
A13: =IFERROR(__xludf.DUMMYFUNCTION("IF(ISBLANK(E13), ""(no BibTex)"", CONCATENATE(REGEXEXTRACT(SUBSTITUTE($E13, ""_"", """"),""@.+{(.+)\d{4}""),"", "",REGEXEXTRACT($E13,""@.+{.+(\d{4}.*),"")))"),"(no BibTex)") -> (no BibTex) | B13: =IF(ISBLANK(D13),IF(ISBLANK(K13),"-",HYPERLINK(K13,"DOC(alt)")), HYPERLINK(CONCAT("https://www.doi.org/",D13),"DOC")) -> - | C13: =IF(ISBLANK(D13),"(no DOI)", HYPERLINK(CONCAT("https://www.doi2bib.org/bib/",D13),"BIB")) -> (no DOI) | G13: =IFERROR(__xludf.DUMMYFUNCTION("IF(ISBLANK(E13),""(no BibTex)"",PROPER(REGEXEXTRACT($E13,""@(.+){"")))"),"(no BibTex)") -> (no BibTex) | H13: =IFERROR(__xludf.DUMMYFUNCTION("IF(ISBLANK(E13),""(no BibTex)"",SUBSTITUTE(IFNA(REGEXEXTRACT($E13,""author += +{(.+)}""),REGEXEXTRACT($E13,""editor *= *{(.+)}"")),"" and"", "",""))"),"(no BibTex)") -> (no BibTex) | I13: =IFERROR(__xludf.DUMMYFUNCTION("IF(ISBLANK(E13),""(no BibTex)"",REGEXEXTRACT($E13,""title *= *{(.+)}""))"),"(no BibTex)") -> (no BibTex) | J13: =IFERROR(__xludf.DUMMYFUNCTION("IFNA(IFNA(REGEXEXTRACT($E13,""journal *= *{(.+)}""), REGEXEXTRACT($E13,""booktitle *= *{(.+)}"")), ""-"")"),"-") -> -
A14: =IFERROR(__xludf.DUMMYFUNCTION("IF(ISBLANK(E14), ""(no BibTex)"", CONCATENATE(REGEXEXTRACT(SUBSTITUTE($E14, ""_"", """"),""@.+{(.+)\d{4}""),"", "",REGEXEXTRACT($E14,""@.+{.+(\d{4}.*),"")))"),"(no BibTex)") -> (no BibTex) | B14: =IF(ISBLANK(D14),IF(ISBLANK(K14),"-",HYPERLINK(K14,"DOC(alt)")), HYPERLINK(CONCAT("https://www.doi.org/",D14),"DOC")) -> - | C14: =IF(ISBLANK(D14),"(no DOI)", HYPERLINK(CONCAT("https://www.doi2bib.org/bib/",D14),"BIB")) -> (no DOI) | G14: =IFERROR(__xludf.DUMMYFUNCTION("IF(ISBLANK(E14),""(no BibTex)"",PROPER(REGEXEXTRACT($E14,""@(.+){"")))"),"(no BibTex)") -> (no BibTex) | H14: =IFERROR(__xludf.DUMMYFUNCTION("IF(ISBLANK(E14),""(no BibTex)"",SUBSTITUTE(IFNA(REGEXEXTRACT($E14,""author += +{(.+)}""),REGEXEXTRACT($E14,""editor *= *{(.+)}"")),"" and"", "",""))"),"(no BibTex)") -> (no BibTex) | I14: =IFERROR(__xludf.DUMMYFUNCTION("IF(ISBLANK(E14),""(no BibTex)"",REGEXEXTRACT($E14,""title *= *{(.+)}""))"),"(no BibTex)") -> (no BibTex) | J14: =IFERROR(__xludf.DUMMYFUNCTION("IFNA(IFNA(REGEXEXTRACT($E14,""journal *= *{(.+)}""), REGEXEXTRACT($E14,""booktitle *= *{(.+)}"")), ""-"")"),"-") -> -
A15: =IFERROR(__xludf.DUMMYFUNCTION("IF(ISBLANK(E15), ""(no BibTex)"", CONCATENATE(REGEXEXTRACT(SUBSTITUTE($E15, ""_"", """"),""@.+{(.+)\d{4}""),"", "",REGEXEXTRACT($E15,""@.+{.+(\d{4}.*),"")))"),"(no BibTex)") -> (no BibTex) | B15: =IF(ISBLANK(D15),IF(ISBLANK(K15),"-",HYPERLINK(K15,"DOC(alt)")), HYPERLINK(CONCAT("https://www.doi.org/",D15),"DOC")) -> - | C15: =IF(ISBLANK(D15),"(no DOI)", HYPERLINK(CONCAT("https://www.doi2bib.org/bib/",D15),"BIB")) -> (no DOI) | G15: =IFERROR(__xludf.DUMMYFUNCTION("IF(ISBLANK(E15),""(no BibTex)"",PROPER(REGEXEXTRACT($E15,""@(.+){"")))"),"(no BibTex)") -> (no BibTex) | H15: =IFERROR(__xludf.DUMMYFUNCTION("IF(ISBLANK(E15),""(no BibTex)"",SUBSTITUTE(IFNA(REGEXEXTRACT($E15,""author += +{(.+)}""),REGEXEXTRACT($E15,""editor *= *{(.+)}"")),"" and"", "",""))"),"(no BibTex)") -> (no BibTex) | I15: =IFERROR(__xludf.DUMMYFUNCTION("IF(ISBLANK(E15),""(no BibTex)"",REGEXEXTRACT($E15,""title *= *{(.+)}""))"),"(no BibTex)") -> (no BibTex) | J15: =IFERROR(__xludf.DUMMYFUNCTION("IFNA(IFNA(REGEXEXTRACT($E15,""journal *= *{(.+)}""), REGEXEXTRACT($E15,""booktitle *= *{(.+)}"")), ""-"")"),"-") -> -
A16: =IFERROR(__xludf.DUMMYFUNCTION("IF(ISBLANK(E16), ""(no BibTex)"", CONCATENATE(REGEXEXTRACT(SUBSTITUTE($E16, ""_"", """"),""@.+{(.+)\d{4}""),"", "",REGEXEXTRACT($E16,""@.+{.+(\d{4}.*),"")))"),"(no BibTex)") -> (no BibTex) | B16: =IF(ISBLANK(D16),IF(ISBLANK(K16),"-",HYPERLINK(K16,"DOC(alt)")), HYPERLINK(CONCAT("https://www.doi.org/",D16),"DOC")) -> - | C16: =IF(ISBLANK(D16),"(no DOI)", HYPERLINK(CONCAT("https://www.doi2bib.org/bib/",D16),"BIB")) -> (no DOI) | G16: =IFERROR(__xludf.DUMMYFUNCTION("IF(ISBLANK(E16),""(no BibTex)"",PROPER(REGEXEXTRACT($E16,""@(.+){"")))"),"(no BibTex)") -> (no BibTex) | H16: =IFERROR(__xludf.DUMMYFUNCTION("IF(ISBLANK(E16),""(no BibTex)"",SUBSTITUTE(IFNA(REGEXEXTRACT($E16,""author += +{(.+)}""),REGEXEXTRACT($E16,""editor *= *{(.+)}"")),"" and"", "",""))"),"(no BibTex)") -> (no BibTex) | I16: =IFERROR(__xludf.DUMMYFUNCTION("IF(ISBLANK(E16),""(no BibTex)"",REGEXEXTRACT($E16,""title *= *{(.+)}""))"),"(no BibTex)") -> (no BibTex) | J16: =IFERROR(__xludf.DUMMYFUNCTION("IFNA(IFNA(REGEXEXTRACT($E16,""journal *= *{(.+)}""), REGEXEXTRACT($E16,""booktitle *= *{(.+)}"")), ""-"")"),"-") -> -
A17: =IFERROR(__xludf.DUMMYFUNCTION("IF(ISBLANK(E17), ""(no BibTex)"", CONCATENATE(REGEXEXTRACT(SUBSTITUTE($E17, ""_"", """"),""@.+{(.+)\d{4}""),"", "",REGEXEXTRACT($E17,""@.+{.+(\d{4}.*),"")))"),"(no BibTex)") -> (no BibTex) | B17: =IF(ISBLANK(D17),IF(ISBLANK(K17),"-",HYPERLINK(K17,"DOC(alt)")), HYPERLINK(CONCAT("https://www.doi.org/",D17),"DOC")) -> - | C17: =IF(ISBLANK(D17),"(no DOI)", HYPERLINK(CONCAT("https://www.doi2bib.org/bib/",D17),"BIB")) -> (no DOI) | G17: =IFERROR(__xludf.DUMMYFUNCTION("IF(ISBLANK(E17),""(no BibTex)"",PROPER(REGEXEXTRACT($E17,""@(.+){"")))"),"(no BibTex)") -> (no BibTex) | H17: =IFERROR(__xludf.DUMMYFUNCTION("IF(ISBLANK(E17),""(no BibTex)"",SUBSTITUTE(IFNA(REGEXEXTRACT($E17,""author += +{(.+)}""),REGEXEXTRACT($E17,""editor *= *{(.+)}"")),"" and"", "",""))"),"(no BibTex)") -> (no BibTex) | I17: =IFERROR(__xludf.DUMMYFUNCTION("IF(ISBLANK(E17),""(no BibTex)"",REGEXEXTRACT($E17,""title *= *{(.+)}""))"),"(no BibTex)") -> (no BibTex) | J17: =IFERROR(__xludf.DUMMYFUNCTION("IFNA(IFNA(REGEXEXTRACT($E17,""journal *= *{(.+)}""), REGEXEXTRACT($E17,""booktitle *= *{(.+)}"")), ""-"")"),"-") -> -
A18: =IFERROR(__xludf.DUMMYFUNCTION("IF(ISBLANK(E18), ""(no BibTex)"", CONCATENATE(REGEXEXTRACT(SUBSTITUTE($E18, ""_"", """"),""@.+{(.+)\d{4}""),"", "",REGEXEXTRACT($E18,""@.+{.+(\d{4}.*),"")))"),"(no BibTex)") -> (no BibTex) | B18: =IF(ISBLANK(D18),IF(ISBLANK(K18),"-",HYPERLINK(K18,"DOC(alt)")), HYPERLINK(CONCAT("https://www.doi.org/",D18),"DOC")) -> - | C18: =IF(ISBLANK(D18),"(no DOI)", HYPERLINK(CONCAT("https://www.doi2bib.org/bib/",D18),"BIB")) -> (no DOI) | G18: =IFERROR(__xludf.DUMMYFUNCTION("IF(ISBLANK(E18),""(no BibTex)"",PROPER(REGEXEXTRACT($E18,""@(.+){"")))"),"(no BibTex)") -> (no BibTex) | H18: =IFERROR(__xludf.DUMMYFUNCTION("IF(ISBLANK(E18),""(no BibTex)"",SUBSTITUTE(IFNA(REGEXEXTRACT($E18,""author += +{(.+)}""),REGEXEXTRACT($E18,""editor *= *{(.+)}"")),"" and"", "",""))"),"(no BibTex)") -> (no BibTex) | I18: =IFERROR(__xludf.DUMMYFUNCTION("IF(ISBLANK(E18),""(no BibTex)"",REGEXEXTRACT($E18,""title *= *{(.+)}""))"),"(no BibTex)") -> (no BibTex) | J18: =IFERROR(__xludf.DUMMYFUNCTION("IFNA(IFNA(REGEXEXTRACT($E18,""journal *= *{(.+)}""), REGEXEXTRACT($E18,""booktitle *= *{(.+)}"")), ""-"")"),"-") -> -
A19: =IFERROR(__xludf.DUMMYFUNCTION("IF(ISBLANK(E19), ""(no BibTex)"", CONCATENATE(REGEXEXTRACT(SUBSTITUTE($E19, ""_"", """"),""@.+{(.+)\d{4}""),"", "",REGEXEXTRACT($E19,""@.+{.+(\d{4}.*),"")))"),"(no BibTex)") -> (no BibTex) | B19: =IF(ISBLANK(D19),IF(ISBLANK(K19),"-",HYPERLINK(K19,"DOC(alt)")), HYPERLINK(CONCAT("https://www.doi.org/",D19),"DOC")) -> - | C19: =IF(ISBLANK(D19),"(no DOI)", HYPERLINK(CONCAT("https://www.doi2bib.org/bib/",D19),"BIB")) -> (no DOI) | G19: =IFERROR(__xludf.DUMMYFUNCTION("IF(ISBLANK(E19),""(no BibTex)"",PROPER(REGEXEXTRACT($E19,""@(.+){"")))"),"(no BibTex)") -> (no BibTex) | H19: =IFERROR(__xludf.DUMMYFUNCTION("IF(ISBLANK(E19),""(no BibTex)"",SUBSTITUTE(IFNA(REGEXEXTRACT($E19,""author += +{(.+)}""),REGEXEXTRACT($E19,""editor *= *{(.+)}"")),"" and"", "",""))"),"(no BibTex)") -> (no BibTex) | I19: =IFERROR(__xludf.DUMMYFUNCTION("IF(ISBLANK(E19),""(no BibTex)"",REGEXEXTRACT($E19,""title *= *{(.+)}""))"),"(no BibTex)") -> (no BibTex) | J19: =IFERROR(__xludf.DUMMYFUNCTION("IFNA(IFNA(REGEXEXTRACT($E19,""journal *= *{(.+)}""), REGEXEXTRACT($E19,""booktitle *= *{(.+)}"")), ""-"")"),"-") -> -
A20: =IFERROR(__xludf.DUMMYFUNCTION("IF(ISBLANK(E20), ""(no BibTex)"", CONCATENATE(REGEXEXTRACT(SUBSTITUTE($E20, ""_"", """"),""@.+{(.+)\d{4}""),"", "",REGEXEXTRACT($E20,""@.+{.+(\d{4}.*),"")))"),"(no BibTex)") -> (no BibTex) | B20: =IF(ISBLANK(D20),IF(ISBLANK(K20),"-",HYPERLINK(K20,"DOC(alt)")), HYPERLINK(CONCAT("https://www.doi.org/",D20),"DOC")) -> - | C20: =IF(ISBLANK(D20),"(no DOI)", HYPERLINK(CONCAT("https://www.doi2bib.org/bib/",D20),"BIB")) -> (no DOI) | G20: =IFERROR(__xludf.DUMMYFUNCTION("IF(ISBLANK(E20),""(no BibTex)"",PROPER(REGEXEXTRACT($E20,""@(.+){"")))"),"(no BibTex)") -> (no BibTex) | H20: =IFERROR(__xludf.DUMMYFUNCTION("IF(ISBLANK(E20),""(no BibTex)"",SUBSTITUTE(IFNA(REGEXEXTRACT($E20,""author += +{(.+)}""),REGEXEXTRACT($E20,""editor *= *{(.+)}"")),"" and"", "",""))"),"(no BibTex)") -> (no BibTex) | I20: =IFERROR(__xludf.DUMMYFUNCTION("IF(ISBLANK(E20),""(no BibTex)"",REGEXEXTRACT($E20,""title *= *{(.+)}""))"),"(no BibTex)") -> (no BibTex) | J20: =IFERROR(__xludf.DUMMYFUNCTION("IFNA(IFNA(REGEXEXTRACT($E20,""journal *= *{(.+)}""), REGEXEXTRACT($E20,""booktitle *= *{(.+)}"")), ""-"")"),"-") -> -
A21: =IFERROR(__xludf.DUMMYFUNCTION("IF(ISBLANK(E21), ""(no BibTex)"", CONCATENATE(REGEXEXTRACT(SUBSTITUTE($E21, ""_"", """"),""@.+{(.+)\d{4}""),"", "",REGEXEXTRACT($E21,""@.+{.+(\d{4}.*),"")))"),"(no BibTex)") -> (no BibTex) | B21: =IF(ISBLANK(D21),IF(ISBLANK(K21),"-",HYPERLINK(K21,"DOC(alt)")), HYPERLINK(CONCAT("https://www.doi.org/",D21),"DOC")) -> - | C21: =IF(ISBLANK(D21),"(no DOI)", HYPERLINK(CONCAT("https://www.doi2bib.org/bib/",D21),"BIB")) -> (no DOI) | G21: =IFERROR(__xludf.DUMMYFUNCTION("IF(ISBLANK(E21),""(no BibTex)"",PROPER(REGEXEXTRACT($E21,""@(.+){"")))"),"(no BibTex)") -> (no BibTex) | H21: =IFERROR(__xludf.DUMMYFUNCTION("IF(ISBLANK(E21),""(no BibTex)"",SUBSTITUTE(IFNA(REGEXEXTRACT($E21,""author += +{(.+)}""),REGEXEXTRACT($E21,""editor *= *{(.+)}"")),"" and"", "",""))"),"(no BibTex)") -> (no BibTex) | I21: =IFERROR(__xludf.DUMMYFUNCTION("IF(ISBLANK(E21),""(no BibTex)"",REGEXEXTRACT($E21,""title *= *{(.+)}""))"),"(no BibTex)") -> (no BibTex) | J21: =IFERROR(__xludf.DUMMYFUNCTION("IFNA(IFNA(REGEXEXTRACT($E21,""journal *= *{(.+)}""), REGEXEXTRACT($E21,""booktitle *= *{(.+)}"")), ""-"")"),"-") -> -
A22: =IFERROR(__xludf.DUMMYFUNCTION("IF(ISBLANK(E22), ""(no BibTex)"", CONCATENATE(REGEXEXTRACT(SUBSTITUTE($E22, ""_"", """"),""@.+{(.+)\d{4}""),"", "",REGEXEXTRACT($E22,""@.+{.+(\d{4}.*),"")))"),"(no BibTex)") -> (no BibTex) | B22: =IF(ISBLANK(D22),IF(ISBLANK(K22),"-",HYPERLINK(K22,"DOC(alt)")), HYPERLINK(CONCAT("https://www.doi.org/",D22),"DOC")) -> - | C22: =IF(ISBLANK(D22),"(no DOI)", HYPERLINK(CONCAT("https://www.doi2bib.org/bib/",D22),"BIB")) -> (no DOI) | G22: =IFERROR(__xludf.DUMMYFUNCTION("IF(ISBLANK(E22),""(no BibTex)"",PROPER(REGEXEXTRACT($E22,""@(.+){"")))"),"(no BibTex)") -> (no BibTex) | H22: =IFERROR(__xludf.DUMMYFUNCTION("IF(ISBLANK(E22),""(no BibTex)"",SUBSTITUTE(IFNA(REGEXEXTRACT($E22,""author += +{(.+)}""),REGEXEXTRACT($E22,""editor *= *{(.+)}"")),"" and"", "",""))"),"(no BibTex)") -> (no BibTex) | I22: =IFERROR(__xludf.DUMMYFUNCTION("IF(ISBLANK(E22),""(no BibTex)"",REGEXEXTRACT($E22,""title *= *{(.+)}""))"),"(no BibTex)") -> (no BibTex) | J22: =IFERROR(__xludf.DUMMYFUNCTION("IFNA(IFNA(REGEXEXTRACT($E22,""journal *= *{(.+)}""), REGEXEXTRACT($E22,""booktitle *= *{(.+)}"")), ""-"")"),"-") -> -
A23: =IFERROR(__xludf.DUMMYFUNCTION("IF(ISBLANK(E23), ""(no BibTex)"", CONCATENATE(REGEXEXTRACT(SUBSTITUTE($E23, ""_"", """"),""@.+{(.+)\d{4}""),"", "",REGEXEXTRACT($E23,""@.+{.+(\d{4}.*),"")))"),"(no BibTex)") -> (no BibTex) | B23: =IF(ISBLANK(D23),IF(ISBLANK(K23),"-",HYPERLINK(K23,"DOC(alt)")), HYPERLINK(CONCAT("https://www.doi.org/",D23),"DOC")) -> - | C23: =IF(ISBLANK(D23),"(no DOI)", HYPERLINK(CONCAT("https://www.doi2bib.org/bib/",D23),"BIB")) -> (no DOI) | G23: =IFERROR(__xludf.DUMMYFUNCTION("IF(ISBLANK(E23),""(no BibTex)"",PROPER(REGEXEXTRACT($E23,""@(.+){"")))"),"(no BibTex)") -> (no BibTex) | H23: =IFERROR(__xludf.DUMMYFUNCTION("IF(ISBLANK(E23),""(no BibTex)"",SUBSTITUTE(IFNA(REGEXEXTRACT($E23,""author += +{(.+)}""),REGEXEXTRACT($E23,""editor *= *{(.+)}"")),"" and"", "",""))"),"(no BibTex)") -> (no BibTex) | I23: =IFERROR(__xludf.DUMMYFUNCTION("IF(ISBLANK(E23),""(no BibTex)"",REGEXEXTRACT($E23,""title *= *{(.+)}""))"),"(no BibTex)") -> (no BibTex) | J23: =IFERROR(__xludf.DUMMYFUNCTION("IFNA(IFNA(REGEXEXTRACT($E23,""journal *= *{(.+)}""), REGEXEXTRACT($E23,""booktitle *= *{(.+)}"")), ""-"")"),"-") -> -
A24: =IFERROR(__xludf.DUMMYFUNCTION("IF(ISBLANK(E24), ""(no BibTex)"", CONCATENATE(REGEXEXTRACT(SUBSTITUTE($E24, ""_"", """"),""@.+{(.+)\d{4}""),"", "",REGEXEXTRACT($E24,""@.+{.+(\d{4}.*),"")))"),"(no BibTex)") -> (no BibTex) | B24: =IF(ISBLANK(D24),IF(ISBLANK(K24),"-",HYPERLINK(K24,"DOC(alt)")), HYPERLINK(CONCAT("https://www.doi.org/",D24),"DOC")) -> - | C24: =IF(ISBLANK(D24),"(no DOI)", HYPERLINK(CONCAT("https://www.doi2bib.org/bib/",D24),"BIB")) -> (no DOI) | G24: =IFERROR(__xludf.DUMMYFUNCTION("IF(ISBLANK(E24),""(no BibTex)"",PROPER(REGEXEXTRACT($E24,""@(.+){"")))"),"(no BibTex)") -> (no BibTex) | H24: =IFERROR(__xludf.DUMMYFUNCTION("IF(ISBLANK(E24),""(no BibTex)"",SUBSTITUTE(IFNA(REGEXEXTRACT($E24,""author += +{(.+)}""),REGEXEXTRACT($E24,""editor *= *{(.+)}"")),"" and"", "",""))"),"(no BibTex)") -> (no BibTex) | I24: =IFERROR(__xludf.DUMMYFUNCTION("IF(ISBLANK(E24),""(no BibTex)"",REGEXEXTRACT($E24,""title *= *{(.+)}""))"),"(no BibTex)") -> (no BibTex) | J24: =IFERROR(__xludf.DUMMYFUNCTION("IFNA(IFNA(REGEXEXTRACT($E24,""journal *= *{(.+)}""), REGEXEXTRACT($E24,""booktitle *= *{(.+)}"")), ""-"")"),"-") -> -
A25: =IFERROR(__xludf.DUMMYFUNCTION("IF(ISBLANK(E25), ""(no BibTex)"", CONCATENATE(REGEXEXTRACT(SUBSTITUTE($E25, ""_"", """"),""@.+{(.+)\d{4}""),"", "",REGEXEXTRACT($E25,""@.+{.+(\d{4}.*),"")))"),"(no BibTex)") -> (no BibTex) | B25: =IF(ISBLANK(D25),IF(ISBLANK(K25),"-",HYPERLINK(K25,"DOC(alt)")), HYPERLINK(CONCAT("https://www.doi.org/",D25),"DOC")) -> - | C25: =IF(ISBLANK(D25),"(no DOI)", HYPERLINK(CONCAT("https://www.doi2bib.org/bib/",D25),"BIB")) -> (no DOI) | G25: =IFERROR(__xludf.DUMMYFUNCTION("IF(ISBLANK(E25),""(no BibTex)"",PROPER(REGEXEXTRACT($E25,""@(.+){"")))"),"(no BibTex)") -> (no BibTex) | H25: =IFERROR(__xludf.DUMMYFUNCTION("IF(ISBLANK(E25),""(no BibTex)"",SUBSTITUTE(IFNA(REGEXEXTRACT($E25,""author += +{(.+)}""),REGEXEXTRACT($E25,""editor *= *{(.+)}"")),"" and"", "",""))"),"(no BibTex)") -> (no BibTex) | I25: =IFERROR(__xludf.DUMMYFUNCTION("IF(ISBLANK(E25),""(no BibTex)"",REGEXEXTRACT($E25,""title *= *{(.+)}""))"),"(no BibTex)") -> (no BibTex) | J25: =IFERROR(__xludf.DUMMYFUNCTION("IFNA(IFNA(REGEXEXTRACT($E25,""journal *= *{(.+)}""), REGEXEXTRACT($E25,""booktitle *= *{(.+)}"")), ""-"")"),"-") -> -
A26: =IFERROR(__xludf.DUMMYFUNCTION("IF(ISBLANK(E26), ""(no BibTex)"", CONCATENATE(REGEXEXTRACT(SUBSTITUTE($E26, ""_"", """"),""@.+{(.+)\d{4}""),"", "",REGEXEXTRACT($E26,""@.+{.+(\d{4}.*),"")))"),"(no BibTex)") -> (no BibTex) | B26: =IF(ISBLANK(D26),IF(ISBLANK(K26),"-",HYPERLINK(K26,"DOC(alt)")), HYPERLINK(CONCAT("https://www.doi.org/",D26),"DOC")) -> - | C26: =IF(ISBLANK(D26),"(no DOI)", HYPERLINK(CONCAT("https://www.doi2bib.org/bib/",D26),"BIB")) -> (no DOI) | G26: =IFERROR(__xludf.DUMMYFUNCTION("IF(ISBLANK(E26),""(no BibTex)"",PROPER(REGEXEXTRACT($E26,""@(.+){"")))"),"(no BibTex)") -> (no BibTex) | H26: =IFERROR(__xludf.DUMMYFUNCTION("IF(ISBLANK(E26),""(no BibTex)"",SUBSTITUTE(IFNA(REGEXEXTRACT($E26,""author += +{(.+)}""),REGEXEXTRACT($E26,""editor *= *{(.+)}"")),"" and"", "",""))"),"(no BibTex)") -> (no BibTex) | I26: =IFERROR(__xludf.DUMMYFUNCTION("IF(ISBLANK(E26),""(no BibTex)"",REGEXEXTRACT($E26,""title *= *{(.+)}""))"),"(no BibTex)") -> (no BibTex) | J26: =IFERROR(__xludf.DUMMYFUNCTION("IFNA(IFNA(REGEXEXTRACT($E26,""journal *= *{(.+)}""), REGEXEXTRACT($E26,""booktitle *= *{(.+)}"")), ""-"")"),"-") -> -
A27: =IFERROR(__xludf.DUMMYFUNCTION("IF(ISBLANK(E27), ""(no BibTex)"", CONCATENATE(REGEXEXTRACT(SUBSTITUTE($E27, ""_"", """"),""@.+{(.+)\d{4}""),"", "",REGEXEXTRACT($E27,""@.+{.+(\d{4}.*),"")))"),"(no BibTex)") -> (no BibTex) | B27: =IF(ISBLANK(D27),IF(ISBLANK(K27),"-",HYPERLINK(K27,"DOC(alt)")), HYPERLINK(CONCAT("https://www.doi.org/",D27),"DOC")) -> - | C27: =IF(ISBLANK(D27),"(no DOI)", HYPERLINK(CONCAT("https://www.doi2bib.org/bib/",D27),"BIB")) -> (no DOI) | G27: =IFERROR(__xludf.DUMMYFUNCTION("IF(ISBLANK(E27),""(no BibTex)"",PROPER(REGEXEXTRACT($E27,""@(.+){"")))"),"(no BibTex)") -> (no BibTex) | H27: =IFERROR(__xludf.DUMMYFUNCTION("IF(ISBLANK(E27),""(no BibTex)"",SUBSTITUTE(IFNA(REGEXEXTRACT($E27,""author += +{(.+)}""),REGEXEXTRACT($E27,""editor *= *{(.+)}"")),"" and"", "",""))"),"(no BibTex)") -> (no BibTex) | I27: =IFERROR(__xludf.DUMMYFUNCTION("IF(ISBLANK(E27),""(no BibTex)"",REGEXEXTRACT($E27,""title *= *{(.+)}""))"),"(no BibTex)") -> (no BibTex) | J27: =IFERROR(__xludf.DUMMYFUNCTION("IFNA(IFNA(REGEXEXTRACT($E27,""journal *= *{(.+)}""), REGEXEXTRACT($E27,""booktitle *= *{(.+)}"")), ""-"")"),"-") -> -
A28: =IFERROR(__xludf.DUMMYFUNCTION("IF(ISBLANK(E28), ""(no BibTex)"", CONCATENATE(REGEXEXTRACT(SUBSTITUTE($E28, ""_"", """"),""@.+{(.+)\d{4}""),"", "",REGEXEXTRACT($E28,""@.+{.+(\d{4}.*),"")))"),"(no BibTex)") -> (no BibTex) | B28: =IF(ISBLANK(D28),IF(ISBLANK(K28),"-",HYPERLINK(K28,"DOC(alt)")), HYPERLINK(CONCAT("https://www.doi.org/",D28),"DOC")) -> - | C28: =IF(ISBLANK(D28),"(no DOI)", HYPERLINK(CONCAT("https://www.doi2bib.org/bib/",D28),"BIB")) -> (no DOI) | G28: =IFERROR(__xludf.DUMMYFUNCTION("IF(ISBLANK(E28),""(no BibTex)"",PROPER(REGEXEXTRACT($E28,""@(.+){"")))"),"(no BibTex)") -> (no BibTex) | H28: =IFERROR(__xludf.DUMMYFUNCTION("IF(ISBLANK(E28),""(no BibTex)"",SUBSTITUTE(IFNA(REGEXEXTRACT($E28,""author += +{(.+)}""),REGEXEXTRACT($E28,""editor *= *{(.+)}"")),"" and"", "",""))"),"(no BibTex)") -> (no BibTex) | I28: =IFERROR(__xludf.DUMMYFUNCTION("IF(ISBLANK(E28),""(no BibTex)"",REGEXEXTRACT($E28,""title *= *{(.+)}""))"),"(no BibTex)") -> (no BibTex) | J28: =IFERROR(__xludf.DUMMYFUNCTION("IFNA(IFNA(REGEXEXTRACT($E28,""journal *= *{(.+)}""), REGEXEXTRACT($E28,""booktitle *= *{(.+)}"")), ""-"")"),"-") -> -
A29: =IFERROR(__xludf.DUMMYFUNCTION("IF(ISBLANK(E29), ""(no BibTex)"", CONCATENATE(REGEXEXTRACT(SUBSTITUTE($E29, ""_"", """"),""@.+{(.+)\d{4}""),"", "",REGEXEXTRACT($E29,""@.+{.+(\d{4}.*),"")))"),"(no BibTex)") -> (no BibTex) | B29: =IF(ISBLANK(D29),IF(ISBLANK(K29),"-",HYPERLINK(K29,"DOC(alt)")), HYPERLINK(CONCAT("https://www.doi.org/",D29),"DOC")) -> - | C29: =IF(ISBLANK(D29),"(no DOI)", HYPERLINK(CONCAT("https://www.doi2bib.org/bib/",D29),"BIB")) -> (no DOI) | G29: =IFERROR(__xludf.DUMMYFUNCTION("IF(ISBLANK(E29),""(no BibTex)"",PROPER(REGEXEXTRACT($E29,""@(.+){"")))"),"(no BibTex)") -> (no BibTex) | H29: =IFERROR(__xludf.DUMMYFUNCTION("IF(ISBLANK(E29),""(no BibTex)"",SUBSTITUTE(IFNA(REGEXEXTRACT($E29,""author += +{(.+)}""),REGEXEXTRACT($E29,""editor *= *{(.+)}"")),"" and"", "",""))"),"(no BibTex)") -> (no BibTex) | I29: =IFERROR(__xludf.DUMMYFUNCTION("IF(ISBLANK(E29),""(no BibTex)"",REGEXEXTRACT($E29,""title *= *{(.+)}""))"),"(no BibTex)") -> (no BibTex) | J29: =IFERROR(__xludf.DUMMYFUNCTION("IFNA(IFNA(REGEXEXTRACT($E29,""journal *= *{(.+)}""), REGEXEXTRACT($E29,""booktitle *= *{(.+)}"")), ""-"")"),"-") -> -
A31: =IFERROR(__xludf.DUMMYFUNCTION("IMPORTRANGE(Settings!$A$2,""wbReferences!A2:W200"")"),"Zhaoping, 2016") -> Zhaoping, 2016 | B31: =IFERROR(__xludf.DUMMYFUNCTION("""COMPUTED_VALUE"""),"DOC") -> DOC | C31: =IFERROR(__xludf.DUMMYFUNCTION("""COMPUTED_VALUE"""),"BIB") -> BIB | D31: =IFERROR(__xludf.DUMMYFUNCTION("""COMPUTED_VALUE"""),"10.1016/j.conb.2016.06.017") -> 10.1016/j.conb.2016.06.017 | E31: =IFERROR(__xludf.DUMMYFUNCTION("""COMPUTED_VALUE"""),"@article{Zhaoping_2016, doi = {10.1016/j.conb.2016.06.017}, url = {https://doi.org/10.1016%2Fj.conb.2016.06.017}, year = 2016, month = {oct}, publisher = {Elsevier {BV}}, volume = {40}, pages = {94--102}, author = {Li Zhaoping}, title = {From the"&" optic tectum to the primary visual cortex: migration through evolution of the saliency map for exogenous attentional guidance}, journal = {Current Opinion in Neurobiology} }") -> @article{Zhaoping_2016, doi = {10.1016/j.conb.2016.06.017}, url = {https://doi.org/10.1016%2Fj.conb.2016.06.017}, year = 2016, month = {oct}, publisher = {Elsevier {BV}}, volume = {40}, pages = {94--102}, author = {Li Zhaoping}, title = {From the optic tectum to the primary visual cortex: migration through evolution of the saliency map for exogenous attentional guidance}, journal = {Current Opinion in Neurobiology} } | G31: =IFERROR(__xludf.DUMMYFUNCTION("""COMPUTED_VALUE"""),"Article") -> Article | H31: =IFERROR(__xludf.DUMMYFUNCTION("""COMPUTED_VALUE"""),"Li Zhaoping") -> Li Zhaoping | I31: =IFERROR(__xludf.DUMMYFUNCTION("""COMPUTED_VALUE"""),"From the optic tectum to the primary visual cortex: migration through evolution of the saliency map for exogenous attentional guidance") -> From the optic tectum to the primary visual cortex: migration through evolution of the saliency map for exogenous attentional guidance | J31: =IFERROR(__xludf.DUMMYFUNCTION("""COMPUTED_VALUE"""),"Current Opinion in Neurobiology") -> Current Opinion in Neurobiology
A32: =IFERROR(__xludf.DUMMYFUNCTION("""COMPUTED_VALUE"""),"Zhang, 2019") -> Zhang, 2019 | B32: =IFERROR(__xludf.DUMMYFUNCTION("""COMPUTED_VALUE"""),"DOC") -> DOC | C32: =IFERROR(__xludf.DUMMYFUNCTION("""COMPUTED_VALUE"""),"BIB") -> BIB | D32: =IFERROR(__xludf.DUMMYFUNCTION("""COMPUTED_VALUE"""),"10.1073/pnas.1817689116") -> 10.1073/pnas.1817689116 | E32: =IFERROR(__xludf.DUMMYFUNCTION("""COMPUTED_VALUE"""),"@article{Zhang_2019, doi = {10.1073/pnas.1817689116}, url = {https://doi.org/10.1073%2Fpnas.1817689116}, year = 2019, month = {jun}, publisher = {Proceedings of the National Academy of Sciences}, volume = {116}, number = {27}, pages = {13592--1360"&"1}, author = {Xu Zhang and Sabato Santaniello}, title = {Role of cerebellar {GABAergic} dysfunctions in the origins of essential tremor}, journal = {Proceedings of the National Academy of Sciences} }") -> @article{Zhang_2019, doi = {10.1073/pnas.1817689116}, url = {https://doi.org/10.1073%2Fpnas.1817689116}, year = 2019, month = {jun}, publisher = {Proceedings of the National Academy of Sciences}, volume = {116}, number = {27}, pages = {13592--13601}, author = {Xu Zhang and Sabato Santaniello}, title = {Role of cerebellar {GABAergic} dysfunctions in the origins of essential tremor}, journal = {Proceedings of the National Academy of Sciences} } | G32: =IFERROR(__xludf.DUMMYFUNCTION("""COMPUTED_VALUE"""),"Article") -> Article | H32: =IFERROR(__xludf.DUMMYFUNCTION("""COMPUTED_VALUE"""),"Xu Zhang, Sabato Santaniello") -> Xu Zhang, Sabato Santaniello | I32: =IFERROR(__xludf.DUMMYFUNCTION("""COMPUTED_VALUE"""),"Role of cerebellar {GABAergic} dysfunctions in the origins of essential tremor") -> Role of cerebellar {GABAergic} dysfunctions in the origins of essential tremor | J32: =IFERROR(__xludf.DUMMYFUNCTION("""COMPUTED_VALUE"""),"Proceedings of the National Academy of Sciences") -> Proceedings of the National Academy of Sciences | L32: =IFERROR(__xludf.DUMMYFUNCTION("""COMPUTED_VALUE"""),"Hiroshi Yamakawa") -> Hiroshi Yamakawa | M32: =IFERROR(__xludf.DUMMYFUNCTION("""COMPUTED_VALUE"""),"HY20Cerebellum") -> HY20Cerebellum
A33: =IFERROR(__xludf.DUMMYFUNCTION("""COMPUTED_VALUE"""),"Zhang, 2016") -> Zhang, 2016 | B33: =IFERROR(__xludf.DUMMYFUNCTION("""COMPUTED_VALUE"""),"DOC") -> DOC | C33: =IFERROR(__xludf.DUMMYFUNCTION("""COMPUTED_VALUE"""),"BIB") -> BIB | D33: =IFERROR(__xludf.DUMMYFUNCTION("""COMPUTED_VALUE"""),"10.1186/s40673-016-0047-1") -> 10.1186/s40673-016-0047-1 | E33: =IFERROR(__xludf.DUMMYFUNCTION("""COMPUTED_VALUE"""),"@article{Zhang_2016, doi = {10.1186/s40673-016-0047-1}, url = {https://doi.org/10.1186%2Fs40673-016-0047-1}, year = 2016, month = {may}, publisher = {Springer Science and Business Media {LLC}}, volume = {3},"&" number = {1}, author = {Xiao-Yang Zhang and Jian-Jun Wang and Jing-Ning Zhu}, title = {Cerebellar fastigial nucleus: from anatomic construction to physiological functions}, journal = {Cerebellum & Ataxias} }") -> @article{Zhang_2016, doi = {10.1186/s40673-016-0047-1}, url = {https://doi.org/10.1186%2Fs40673-016-0047-1}, year = 2016, month = {may}, publisher = {Springer Science and Business Media {LLC}}, volume = {3}, number = {1}, author = {Xiao-Yang Zhang and Jian-Jun Wang and Jing-Ning Zhu}, title = {Cerebellar fastigial nucleus: from anatomic construction to physiological functions}, journal = {Cerebellum & Ataxias} } | G33: =IFERROR(__xludf.DUMMYFUNCTION("""COMPUTED_VALUE"""),"Article") -> Article | H33: =IFERROR(__xludf.DUMMYFUNCTION("""COMPUTED_VALUE"""),"Xiao-Yang Zhang, Jian-Jun Wang, Jing-Ning Zhu") -> Xiao-Yang Zhang, Jian-Jun Wang, Jing-Ning Zhu | I33: =IFERROR(__xludf.DUMMYFUNCTION("""COMPUTED_VALUE"""),"Cerebellar fastigial nucleus: from anatomic construction to physiological functions") -> Cerebellar fastigial nucleus: from anatomic construction to physiological functions | J33: =IFERROR(__xludf.DUMMYFUNCTION("""COMPUTED_VALUE"""),"Cerebellum & Ataxias") -> Cerebellum & Ataxias | L33: =IFERROR(__xludf.DUMMYFUNCTION("""COMPUTED_VALUE"""),"Yoshinasa Tawatsji") -> Yoshinasa Tawatsji | M33: =IFERROR(__xludf.DUMMYFUNCTION("""COMPUTED_VALUE"""),"Oculomotor") -> Oculomotor
A34: =IFERROR(__xludf.DUMMYFUNCTION("""COMPUTED_VALUE"""),"Yamakawa, 2020") -> Yamakawa, 2020 | B34: =IFERROR(__xludf.DUMMYFUNCTION("""COMPUTED_VALUE"""),"DOC") -> DOC | C34: =IFERROR(__xludf.DUMMYFUNCTION("""COMPUTED_VALUE"""),"BIB") -> BIB | D34: =IFERROR(__xludf.DUMMYFUNCTION("""COMPUTED_VALUE"""),"10.3389/fncom.2020.00074") -> 10.3389/fncom.2020.00074 | E34: =IFERROR(__xludf.DUMMYFUNCTION("""COMPUTED_VALUE"""),"@article{Yamakawa_2020, doi = {10.3389/fncom.2020.00074}, url = {https://doi.org/10.3389%2Ffncom.2020.00074}, year = 2020, month = {aug}, publisher = {Frontiers Media {SA}}, volume = {14}, author = {Hiroshi Yamakawa}, title = {Revealing the Comput"&"ational Meaning of Neocortical Interarea Signals}, journal = {Frontiers in Computational Neuroscience} }") -> @article{Yamakawa_2020, doi = {10.3389/fncom.2020.00074}, url = {https://doi.org/10.3389%2Ffncom.2020.00074}, year = 2020, month = {aug}, publisher = {Frontiers Media {SA}}, volume = {14}, author = {Hiroshi Yamakawa}, title = {Revealing the Computational Meaning of Neocortical Interarea Signals}, journal = {Frontiers in Computational Neuroscience} } | G34: =IFERROR(__xludf.DUMMYFUNCTION("""COMPUTED_VALUE"""),"Article") -> Article | H34: =IFERROR(__xludf.DUMMYFUNCTION("""COMPUTED_VALUE"""),"Hiroshi Yamakawa") -> Hiroshi Yamakawa | I34: =IFERROR(__xludf.DUMMYFUNCTION("""COMPUTED_VALUE"""),"Revealing the Computational Meaning of Neocortical Interarea Signals") -> Revealing the Computational Meaning of Neocortical Interarea Signals | J34: =IFERROR(__xludf.DUMMYFUNCTION("""COMPUTED_VALUE"""),"Frontiers in Computational Neuroscience") -> Frontiers in Computational Neuroscience | K34: =IFERROR(__xludf.DUMMYFUNCTION("""COMPUTED_VALUE"""),"https://www.frontiersin.org/articles/10.3389/fncom.2020.00074/full") -> https://www.frontiersin.org/articles/10.3389/fncom.2020.00074/full | L34: =IFERROR(__xludf.DUMMYFUNCTION("""COMPUTED_VALUE"""),"Hiroshi Yamakawa") -> Hiroshi Yamakawa | M34: =IFERROR(__xludf.DUMMYFUNCTION("""COMPUTED_VALUE"""),"HY18NeocorticalInterareaSignals") -> HY18NeocorticalInterareaSignals
A35: =IFERROR(__xludf.DUMMYFUNCTION("""COMPUTED_VALUE"""),"Yamakawa, 2020a") -> Yamakawa, 2020a | B35: =IFERROR(__xludf.DUMMYFUNCTION("""COMPUTED_VALUE"""),"DOC") -> DOC | C35: =IFERROR(__xludf.DUMMYFUNCTION("""COMPUTED_VALUE"""),"BIB") -> BIB | D35: =IFERROR(__xludf.DUMMYFUNCTION("""COMPUTED_VALUE"""),"10.1007/s00354-019-00081-z") -> 10.1007/s00354-019-00081-z | E35: =IFERROR(__xludf.DUMMYFUNCTION("""COMPUTED_VALUE"""),"@article{Yamakawa_2020a, doi = {10.1007/s00354-019-00081-z}, url = {https://doi.org/10.1007%2Fs00354-019-00081-z}, year = 2020, month = {jan}, publisher = {Springer Science and Business Media {LLC}}, volume "&"= {38}, number = {1}, pages = {49--64}, author = {Hiroshi Yamakawa}, title = {Attentional Reinforcement Learning in the Brain}, journal = {New Generation Computing} }") -> @article{Yamakawa_2020a, doi = {10.1007/s00354-019-00081-z}, url = {https://doi.org/10.1007%2Fs00354-019-00081-z}, year = 2020, month = {jan}, publisher = {Springer Science and Business Media {LLC}}, volume = {38}, number = {1}, pages = {49--64}, author = {Hiroshi Yamakawa}, title = {Attentional Reinforcement Learning in the Brain}, journal = {New Generation Computing} } | F35: =IFERROR(__xludf.DUMMYFUNCTION("""COMPUTED_VALUE"""),"Hypothesis") -> Hypothesis | G35: =IFERROR(__xludf.DUMMYFUNCTION("""COMPUTED_VALUE"""),"Article") -> Article | H35: =IFERROR(__xludf.DUMMYFUNCTION("""COMPUTED_VALUE"""),"Hiroshi Yamakawa") -> Hiroshi Yamakawa | I35: =IFERROR(__xludf.DUMMYFUNCTION("""COMPUTED_VALUE"""),"Attentional Reinforcement Learning in the Brain") -> Attentional Reinforcement Learning in the Brain | J35: =IFERROR(__xludf.DUMMYFUNCTION("""COMPUTED_VALUE"""),"New Generation Computing") -> New Generation Computing | L35: =IFERROR(__xludf.DUMMYFUNCTION("""COMPUTED_VALUE"""),"Hiroshi Yamakawa") -> Hiroshi Yamakawa | M35: =IFERROR(__xludf.DUMMYFUNCTION("""COMPUTED_VALUE"""),"HY18NeocorticalInterareaSignals") -> HY18NeocorticalInterareaSignals
A36: =IFERROR(__xludf.DUMMYFUNCTION("""COMPUTED_VALUE"""),"Wolpert, 1998") -> Wolpert, 1998 | B36: =IFERROR(__xludf.DUMMYFUNCTION("""COMPUTED_VALUE"""),"DOC") -> DOC | C36: =IFERROR(__xludf.DUMMYFUNCTION("""COMPUTED_VALUE"""),"BIB") -> BIB | D36: =IFERROR(__xludf.DUMMYFUNCTION("""COMPUTED_VALUE"""),"10.1016/S1364-6613(98)01221-2") -> 10.1016/S1364-6613(98)01221-2 | E36: =IFERROR(__xludf.DUMMYFUNCTION("""COMPUTED_VALUE"""),"@article{Wolpert_1998, doi = {10.1016/s1364-6613(98)01221-2}, url = {https://doi.org/10.1016%2Fs1364-6613%2898%2901221-2}, year = 1998, month = {sep}, publisher = {Elsevier {BV}}, volume = {2}, number = {9}, pages = {338--347}, author = {Daniel M"&" Wolpert and R.Chris Miall and Mitsuo Kawato}, title = {Internal models in the cerebellum}, journal = {Trends in Cognitive Sciences} }") -> @article{Wolpert_1998, doi = {10.1016/s1364-6613(98)01221-2}, url = {https://doi.org/10.1016%2Fs1364-6613%2898%2901221-2}, year = 1998, month = {sep}, publisher = {Elsevier {BV}}, volume = {2}, number = {9}, pages = {338--347}, author = {Daniel M Wolpert and R.Chris Miall and Mitsuo Kawato}, title = {Internal models in the cerebellum}, journal = {Trends in Cognitive Sciences} } | G36: =IFERROR(__xludf.DUMMYFUNCTION("""COMPUTED_VALUE"""),"Article") -> Article | H36: =IFERROR(__xludf.DUMMYFUNCTION("""COMPUTED_VALUE"""),"Daniel M Wolpert, R.Chris Miall, Mitsuo Kawato") -> Daniel M Wolpert, R.Chris Miall, Mitsuo Kawato | I36: =IFERROR(__xludf.DUMMYFUNCTION("""COMPUTED_VALUE"""),"Internal models in the cerebellum") -> Internal models in the cerebellum | J36: =IFERROR(__xludf.DUMMYFUNCTION("""COMPUTED_VALUE"""),"Trends in Cognitive Sciences") -> Trends in Cognitive Sciences | L36: =IFERROR(__xludf.DUMMYFUNCTION("""COMPUTED_VALUE"""),"Hiroshi Yamakawa") -> Hiroshi Yamakawa | M36: =IFERROR(__xludf.DUMMYFUNCTION("""COMPUTED_VALUE"""),"HY20Cerebellum") -> HY20Cerebellum
A37: =IFERROR(__xludf.DUMMYFUNCTION("""COMPUTED_VALUE"""),"Witter, 2000") -> Witter, 2000 | B37: =IFERROR(__xludf.DUMMYFUNCTION("""COMPUTED_VALUE"""),"DOC") -> DOC | C37: =IFERROR(__xludf.DUMMYFUNCTION("""COMPUTED_VALUE"""),"BIB") -> BIB | D37: =IFERROR(__xludf.DUMMYFUNCTION("""COMPUTED_VALUE"""),"10.1002/1098-1063(2000)10:4<398::aid-hipo6>3.0.co;2-k") -> 10.1002/1098-1063(2000)10:4<398::aid-hipo6>3.0.co;2-k | E37: =IFERROR(__xludf.DUMMYFUNCTION("""COMPUTED_VALUE"""),"@article{Witter_2000, doi = {10.1002/1098-1063(2000)10:4<398::aid-hipo6>3.0.co;2-k}, url = {https://doi.org/10.1002%2F1098-1063%282000%2910%3A4%3C398%3A%3Aaid-hipo6%3E3.0.co%3B2-k}, year = 2000, publisher = {Wiley}, volume = {10}, number = {4}, pag"&"es = {398--410}, author = {Menno P. Witter and Pieterke A. Naber and Theo van Haeften and Willem C.M. Machielsen and Serge A.R.B. Rombouts and Frederik Barkhof and Philip Scheltens and Fernando H. Lopes da Silva}, title = {Cortico-hippocampal communicat"&"ion by way of parallel parahippocampal-subicular pathways}, journal = {Hippocampus} }") -> @article{Witter_2000, doi = {10.1002/1098-1063(2000)10:4<398::aid-hipo6>3.0.co;2-k}, url = {https://doi.org/10.1002%2F1098-1063%282000%2910%3A4%3C398%3A%3Aaid-hipo6%3E3.0.co%3B2-k}, year = 2000, publisher = {Wiley}, volume = {10}, number = {4}, pages = {398--410}, author = {Menno P. Witter and Pieterke A. Naber and Theo van Haeften and Willem C.M. Machielsen and Serge A.R.B. Rombouts and Frederik Barkhof and Philip Scheltens and Fernando H. Lopes da Silva}, title = {Cortico-hippocampal communication by way of parallel parahippocampal-subicular pathways}, journal = {Hippocampus} } | F37: =IFERROR(__xludf.DUMMYFUNCTION("""COMPUTED_VALUE"""),"Review") -> Review | G37: =IFERROR(__xludf.DUMMYFUNCTION("""COMPUTED_VALUE"""),"Article") -> Article | H37: =IFERROR(__xludf.DUMMYFUNCTION("""COMPUTED_VALUE"""),"Menno P. Witter, Pieterke A. Naber, Theo van Haeften, Willem C.M. Machielsen, Serge A.R.B. Rombouts, Frederik Barkhof, Philip Scheltens, Fernando H. Lopes da Silva") -> Menno P. Witter, Pieterke A. Naber, Theo van Haeften, Willem C.M. Machielsen, Serge A.R.B. Rombouts, Frederik Barkhof, Philip Scheltens, Fernando H. Lopes da Silva | I37: =IFERROR(__xludf.DUMMYFUNCTION("""COMPUTED_VALUE"""),"Cortico-hippocampal communication by way of parallel parahippocampal-subicular pathways") -> Cortico-hippocampal communication by way of parallel parahippocampal-subicular pathways | J37: =IFERROR(__xludf.DUMMYFUNCTION("""COMPUTED_VALUE"""),"Hippocampus") -> Hippocampus | L37: =IFERROR(__xludf.DUMMYFUNCTION("""COMPUTED_VALUE"""),"Ayako Fukawa") -> Ayako Fukawa | M37: =IFERROR(__xludf.DUMMYFUNCTION("""COMPUTED_VALUE"""),"AT20HippocampalFormation") -> AT20HippocampalFormation
A38: =IFERROR(__xludf.DUMMYFUNCTION("""COMPUTED_VALUE"""),"White, 2017") -> White, 2017 | B38: =IFERROR(__xludf.DUMMYFUNCTION("""COMPUTED_VALUE"""),"DOC") -> DOC | C38: =IFERROR(__xludf.DUMMYFUNCTION("""COMPUTED_VALUE"""),"BIB") -> BIB | D38: =IFERROR(__xludf.DUMMYFUNCTION("""COMPUTED_VALUE"""),"10.1073/pnas.1701003114") -> 10.1073/pnas.1701003114 | E38: =IFERROR(__xludf.DUMMYFUNCTION("""COMPUTED_VALUE"""),"@article{White_2017, doi = {10.1073/pnas.1701003114}, url = {https://doi.org/10.1073%2Fpnas.1701003114}, year = 2017, month = {aug}, publisher = {Proceedings of the National Academy of Sciences}, volume = {114}, number = {35}, pages = {9451--9456}"&", author = {Brian J. White and Janis Y. Kan and Ron Levy and Laurent Itti and Douglas P. Munoz}, title = {Superior colliculus encodes visual saliency before the primary visual cortex}, journal = {Proceedings of the National Academy of Sciences} }") -> @article{White_2017, doi = {10.1073/pnas.1701003114}, url = {https://doi.org/10.1073%2Fpnas.1701003114}, year = 2017, month = {aug}, publisher = {Proceedings of the National Academy of Sciences}, volume = {114}, number = {35}, pages = {9451--9456}, author = {Brian J. White and Janis Y. Kan and Ron Levy and Laurent Itti and Douglas P. Munoz}, title = {Superior colliculus encodes visual saliency before the primary visual cortex}, journal = {Proceedings of the National Academy of Sciences} } | G38: =IFERROR(__xludf.DUMMYFUNCTION("""COMPUTED_VALUE"""),"Article") -> Article | H38: =IFERROR(__xludf.DUMMYFUNCTION("""COMPUTED_VALUE"""),"Brian J. White, Janis Y. Kan, Ron Levy, Laurent Itti, Douglas P. Munoz") -> Brian J. White, Janis Y. Kan, Ron Levy, Laurent Itti, Douglas P. Munoz | I38: =IFERROR(__xludf.DUMMYFUNCTION("""COMPUTED_VALUE"""),"Superior colliculus encodes visual saliency before the primary visual cortex") -> Superior colliculus encodes visual saliency before the primary visual cortex | J38: =IFERROR(__xludf.DUMMYFUNCTION("""COMPUTED_VALUE"""),"Proceedings of the National Academy of Sciences") -> Proceedings of the National Academy of Sciences
A39: =IFERROR(__xludf.DUMMYFUNCTION("""COMPUTED_VALUE"""),"Wei, 2016") -> Wei, 2016 | B39: =IFERROR(__xludf.DUMMYFUNCTION("""COMPUTED_VALUE"""),"DOC") -> DOC | C39: =IFERROR(__xludf.DUMMYFUNCTION("""COMPUTED_VALUE"""),"BIB") -> BIB | D39: =IFERROR(__xludf.DUMMYFUNCTION("""COMPUTED_VALUE"""),"10.1523/JNEUROSCI.3648-15.2016") -> 10.1523/JNEUROSCI.3648-15.2016 | E39: =IFERROR(__xludf.DUMMYFUNCTION("""COMPUTED_VALUE"""),"@article{Wei_2016, doi = {10.1523/jneurosci.3648-15.2016}, url = {https://doi.org/10.1523%2Fjneurosci.3648-15.2016}, year = 2016, month = {apr}, publisher = {Society for Neuroscience}, volume = {36}, number = {15}, pages = {4231--4247}, author = "&"{Yina Wei and Giri P. Krishnan and Maxim Bazhenov}, title = {Synaptic Mechanisms of Memory Consolidation during Sleep Slow Oscillations}, journal = {The Journal of Neuroscience} }") -> @article{Wei_2016, doi = {10.1523/jneurosci.3648-15.2016}, url = {https://doi.org/10.1523%2Fjneurosci.3648-15.2016}, year = 2016, month = {apr}, publisher = {Society for Neuroscience}, volume = {36}, number = {15}, pages = {4231--4247}, author = {Yina Wei and Giri P. Krishnan and Maxim Bazhenov}, title = {Synaptic Mechanisms of Memory Consolidation during Sleep Slow Oscillations}, journal = {The Journal of Neuroscience} } | G39: =IFERROR(__xludf.DUMMYFUNCTION("""COMPUTED_VALUE"""),"Article") -> Article | H39: =IFERROR(__xludf.DUMMYFUNCTION("""COMPUTED_VALUE"""),"Yina Wei, Giri P. Krishnan, Maxim Bazhenov") -> Yina Wei, Giri P. Krishnan, Maxim Bazhenov | I39: =IFERROR(__xludf.DUMMYFUNCTION("""COMPUTED_VALUE"""),"Synaptic Mechanisms of Memory Consolidation during Sleep Slow Oscillations") -> Synaptic Mechanisms of Memory Consolidation during Sleep Slow Oscillations | J39: =IFERROR(__xludf.DUMMYFUNCTION("""COMPUTED_VALUE"""),"The Journal of Neuroscience") -> The Journal of Neuroscience | K39: =IFERROR(__xludf.DUMMYFUNCTION("""COMPUTED_VALUE"""),"Fig.1") -> Fig.1 | L39: =IFERROR(__xludf.DUMMYFUNCTION("""COMPUTED_VALUE"""),"Hiroshi Yamakawa") -> Hiroshi Yamakawa | M39: =IFERROR(__xludf.DUMMYFUNCTION("""COMPUTED_VALUE"""),"HY18NeocorticalInterareaSignals") -> HY18NeocorticalInterareaSignals
A40: =IFERROR(__xludf.DUMMYFUNCTION("""COMPUTED_VALUE"""),"Wang, 2021") -> Wang, 2021 | B40: =IFERROR(__xludf.DUMMYFUNCTION("""COMPUTED_VALUE"""),"DOC") -> DOC | C40: =IFERROR(__xludf.DUMMYFUNCTION("""COMPUTED_VALUE"""),"BIB") -> BIB | D40: =IFERROR(__xludf.DUMMYFUNCTION("""COMPUTED_VALUE"""),"10.1002/jnr.24993") -> 10.1002/jnr.24993 | E40: =IFERROR(__xludf.DUMMYFUNCTION("""COMPUTED_VALUE"""),"@article{Wang2021, doi = {10.1002/jnr.24993}, url = {https://doi.org/10.1002/jnr.24993}, year = {2021}, month = dec, publisher = {Wiley}, volume = {100}, number = {2}, pages = {620--637}, author = {Xiaolu Wang and Manuele Novell"&"o and Zhenyu Gao and Tom J. H. Ruigrok and Chris I. De Zeeuw}, title = {Input and output organization of the mesodiencephalic junction for cerebro-cerebellar communication}, journal = {Journal of Neuroscience Research} }") -> @article{Wang2021, doi = {10.1002/jnr.24993}, url = {https://doi.org/10.1002/jnr.24993}, year = {2021}, month = dec, publisher = {Wiley}, volume = {100}, number = {2}, pages = {620--637}, author = {Xiaolu Wang and Manuele Novello and Zhenyu Gao and Tom J. H. Ruigrok and Chris I. De Zeeuw}, title = {Input and output organization of the mesodiencephalic junction for cerebro-cerebellar communication}, journal = {Journal of Neuroscience Research} } | G40: =IFERROR(__xludf.DUMMYFUNCTION("""COMPUTED_VALUE"""),"Article") -> Article | H40: =IFERROR(__xludf.DUMMYFUNCTION("""COMPUTED_VALUE"""),"Xiaolu Wang, Manuele Novello, Zhenyu Gao, Tom J. H. Ruigrok, Chris I. De Zeeuw") -> Xiaolu Wang, Manuele Novello, Zhenyu Gao, Tom J. H. Ruigrok, Chris I. De Zeeuw | I40: =IFERROR(__xludf.DUMMYFUNCTION("""COMPUTED_VALUE"""),"Input and output organization of the mesodiencephalic junction for cerebro-cerebellar communication") -> Input and output organization of the mesodiencephalic junction for cerebro-cerebellar communication | J40: =IFERROR(__xludf.DUMMYFUNCTION("""COMPUTED_VALUE"""),"Journal of Neuroscience Research") -> Journal of Neuroscience Research | L40: =IFERROR(__xludf.DUMMYFUNCTION("""COMPUTED_VALUE"""),"Hiroshi Yamakawa") -> Hiroshi Yamakawa | M40: =IFERROR(__xludf.DUMMYFUNCTION("""COMPUTED_VALUE"""),"HY20Cerebellum") -> HY20Cerebellum
A41: =IFERROR(__xludf.DUMMYFUNCTION("""COMPUTED_VALUE"""),"Wang, 2020") -> Wang, 2020 | B41: =IFERROR(__xludf.DUMMYFUNCTION("""COMPUTED_VALUE"""),"DOC") -> DOC | C41: =IFERROR(__xludf.DUMMYFUNCTION("""COMPUTED_VALUE"""),"BIB") -> BIB | D41: =IFERROR(__xludf.DUMMYFUNCTION("""COMPUTED_VALUE"""),"10.1016/j.cell.2020.04.007") -> 10.1016/j.cell.2020.04.007 | E41: =IFERROR(__xludf.DUMMYFUNCTION("""COMPUTED_VALUE"""),"@article{Wang_2020, doi = {10.1016/j.cell.2020.04.007}, url = {https://doi.org/10.1016%2Fj.cell.2020.04.007}, year = 2020, month = {may}, publisher = {Elsevier {BV}}, volume = {181}, number = {4}, pages = {936--953.e20}, author = {Quanxin Wang an"&"d Song-Lin Ding and Yang Li and Josh Royall and David Feng and Phil Lesnar and Nile Graddis and Maitham Naeemi and Benjamin Facer and Anh Ho and Tim Dolbeare and Brandon Blanchard and Nick Dee and Wayne Wakeman and Karla E. Hirokawa and Aaron Szafer and S"&"usan M. Sunkin and Seung Wook Oh and Amy Bernard and John W. Phillips and Michael Hawrylycz and Christof Koch and Hongkui Zeng and Julie A. Harris and Lydia Ng}, title = {The Allen Mouse Brain Common Coordinate Framework: A 3D Reference Atlas}, journal "&"= {Cell} }") -> @article{Wang_2020, doi = {10.1016/j.cell.2020.04.007}, url = {https://doi.org/10.1016%2Fj.cell.2020.04.007}, year = 2020, month = {may}, publisher = {Elsevier {BV}}, volume = {181}, number = {4}, pages = {936--953.e20}, author = {Quanxin Wang and Song-Lin Ding and Yang Li and Josh Royall and David Feng and Phil Lesnar and Nile Graddis and Maitham Naeemi and Benjamin Facer and Anh Ho and Tim Dolbeare and Brandon Blanchard and Nick Dee and Wayne Wakeman and Karla E. Hirokawa and Aaron Szafer and Susan M. Sunkin and Seung Wook Oh and Amy Bernard and John W. Phillips and Michael Hawrylycz and Christof Koch and Hongkui Zeng and Julie A. Harris and Lydia Ng}, title = {The Allen Mouse Brain Common Coordinate Framework: A 3D Reference Atlas}, journal = {Cell} } | G41: =IFERROR(__xludf.DUMMYFUNCTION("""COMPUTED_VALUE"""),"Article") -> Article | H41: =IFERROR(__xludf.DUMMYFUNCTION("""COMPUTED_VALUE"""),"Quanxin Wang, Song-Lin Ding, Yang Li, Josh Royall, David Feng, Phil Lesnar, Nile Graddis, Maitham Naeemi, Benjamin Facer, Anh Ho, Tim Dolbeare, Brandon Blanchard, Nick Dee, Wayne Wakeman, Karla E. Hirokawa, Aaron Szafer, Susan M. Sunkin, Seung Wook Oh, Am"&"y Bernard, John W. Phillips, Michael Hawrylycz, Christof Koch, Hongkui Zeng, Julie A. Harris, Lydia Ng") -> Quanxin Wang, Song-Lin Ding, Yang Li, Josh Royall, David Feng, Phil Lesnar, Nile Graddis, Maitham Naeemi, Benjamin Facer, Anh Ho, Tim Dolbeare, Brandon Blanchard, Nick Dee, Wayne Wakeman, Karla E. Hirokawa, Aaron Szafer, Susan M. Sunkin, Seung Wook Oh, Amy Bernard, John W. Phillips, Michael Hawrylycz, Christof Koch, Hongkui Zeng, Julie A. Harris, Lydia Ng | I41: =IFERROR(__xludf.DUMMYFUNCTION("""COMPUTED_VALUE"""),"The Allen Mouse Brain Common Coordinate Framework: A 3D Reference Atlas") -> The Allen Mouse Brain Common Coordinate Framework: A 3D Reference Atlas | J41: =IFERROR(__xludf.DUMMYFUNCTION("""COMPUTED_VALUE"""),"Cell") -> Cell
...

Sheet Circuits
